{"uuid": "8d46f870-59a8-4fd7-913c-667bb91063b5", "children": ["25cd9627-59eb-4552-b016-c0b3dae95bab", "8de083d1-61cf-4d74-ac66-63521680ea6d"], "befores": [{"name": "test_setup", "status": "passed", "start": 1598586483946, "stop": 1598586490359}], "afters": [{"name": "test_setup::0", "status": "broken", "statusDetails": {"message": "selenium.common.exceptions.WebDriverException: Message: chrome not reachable\n  (Session info: chrome=84.0.4147.135)\n\n", "trace": "  File \"C:\\Users\\hp\\AppData\\Local\\Programs\\Python\\Python38-32\\lib\\site-packages\\allure_commons\\_allure.py\", line 185, in __call__\n    return self._fixture_function(*args, **kwargs)\n  File \"C:\\Users\\hp\\AppData\\Local\\Programs\\Python\\Python38-32\\lib\\site-packages\\_pytest\\fixtures.py\", line 932, in _teardown_yield_fixture\n    next(it)\n  File \"C:\\Users\\hp\\PycharmProjects\\automation_1\\tests\\conftest.py\", line 21, in test_setup\n    driver.close()\n  File \"C:\\Users\\hp\\AppData\\Local\\Programs\\Python\\Python38-32\\lib\\site-packages\\selenium\\webdriver\\remote\\webdriver.py\", line 688, in close\n    self.execute(Command.CLOSE)\n  File \"C:\\Users\\hp\\AppData\\Local\\Programs\\Python\\Python38-32\\lib\\site-packages\\selenium\\webdriver\\remote\\webdriver.py\", line 321, in execute\n    self.error_handler.check_response(response)\n  File \"C:\\Users\\hp\\AppData\\Local\\Programs\\Python\\Python38-32\\lib\\site-packages\\selenium\\webdriver\\remote\\errorhandler.py\", line 242, in check_response\n    raise exception_class(message, screen, stacktrace)\n"}, "start": 1598586551819, "stop": 1598586555919}], "start": 1598586483946, "stop": 1598586555919}